Workbook

Sheet Nasil_Kullanilir
A1: Yıllık İzin Takip Sistemi
A2: Tüm personel verileri SAHTEDİR. Orijinal dosya paylaşılamadığı için yapı yeniden kurulmuştur.
A4: Her yeni İK datası geldiğinde
A5: 1. Veri_Guncel sayfasındaki veriyi Veri_Onceki'ye taşıyın (A–H sütunları, değer olarak). Ayarlar'da önceki data tarihini güncelleyin.
A6: 2. Yeni İK datasını Veri_Guncel'e yapıştırın (A–H sütunları, aynı sıra). Ayarlar'da güncel data tarihini girin.
A7: 3. Datada kapsam dışı bölgeler de varsa (tüm Türkiye datası) ayıklama otomatiktir: yalnızca Ayarlar'daki bölge listesi hesaplara girer.
A8: 4. Ozet: bölge bazında biriken izin, 14 ve 20 gün üstü kişi sayısı, alarm, önceki döneme göre değişim ve grafikler.
A9: 5. Liste_14_Gun: bakiyesi 14 gün ve üzeri olanlar, büyükten küçüğe. Ayarlar'dan bölge seçilirse yalnızca o bölge listelenir; üstteki bilgilendirme metni bölge müdürüne gönderilecek e-postanın taslağıdır.
A11: Hesaplar (4857 sayılı İş Kanunu, madde 53)
A12: Kıdem 1–5 yıl: 14 gün · 5–15 yıl: 20 gün · 15 yıl ve üzeri: 26 gün · 18 yaş ve altı ile 50 yaş ve üzeri: en az 20 gün · 1 yıldan az: hak yok
A13: Sonraki hak ediş tarihi = işe giriş tarihinin bir sonraki yıldönümü
A14: Dönemde kullanılan izin = önceki bakiye + iki data arasında kazanılan hak − güncel bakiye
... A17: Renk kodu: mavi = girilen değer · sarı zemin = her dönem güncellenen hücre · siyah = formül · yeşil = başka sayfadan gelen değer

Sheet Ozet
A1: ="Bölge İzin Özeti — "&TEXT(Ayarlar!$B$3,"dd.mm.yyyy")&" (önceki: "&TEXT(Ayarlar!$B$4,"dd.mm.yyyy")&")" -> Bölge İzin Özeti — 14.09.2026 (önceki: 31.07.2026)
A3: Bölge | B3: Personel | C3: Biriken İzin (gün) | D3: Kişi Başı | E3: 14+ Gün (kişi) | F3: 20+ Gün (kişi) | G3: Alarm | H3: Hak Ediş Yaklaşan | I3: Dönemde Kullanılan (gün) | J3: Önceki Biriken (gün) | K3: Değişim (gün) | L3: Yeni Personel | M3: Ayrılan
A4: =Ayarlar!A15 -> Bölge 1 | B4: =COUNTIFS(Takip!$C$2:$C$501,A4,Takip!$G$2:$G$501,1) -> 23 | C4: =SUMIFS(Takip!$M$2:$M$501,Takip!$C$2:$C$501,A4) -> 235 | D4: =IF(B4=0,0,C4/B4) -> 10.217391 | E4: =COUNTIFS(Takip!$C$2:$C$501,A4,Takip!$M$2:$M$501,">="&Ayarlar!$B$6) -> 8 | F4: =COUNTIFS(Takip!$C$2:$C$501,A4,Takip!$M$2:$M$501,">="&Ayarlar!$B$7) -> 3 | G4: =IF(F4>=Ayarlar!$B$8,"▲ ALARM",IF(E4>0,"● Planla","✓")) -> ● Planla | H4: =COUNTIFS(Takip!$C$2:$C$501,A4,Takip!$R$2:$R$501,"Evet") -> 3 | I4: =SUMIFS(Takip!$P$2:$P$501,Takip!$C$2:$C$501,A4) -> 72 | J4: =SUMIFS(Veri_Onceki!$H:$H,Veri_Onceki!$C:$C,A4) -> 267 | K4: =C4-J4 -> -32 | L4: =COUNTIFS(Takip!$C$2:$C$501,A4,Takip!$S$2:$S$501,"Yeni personel") -> 1 | M4: =COUNTIFS(Veri_Onceki!$C:$C,A4,Veri_Onceki!$I:$I,1) -> 0
A5: =Ayarlar!A16 -> Bölge 2 | B5: =COUNTIFS(Takip!$C$2:$C$501,A5,Takip!$G$2:$G$501,1) -> 20 | C5: =SUMIFS(Takip!$M$2:$M$501,Takip!$C$2:$C$501,A5) -> 231 | D5: =IF(B5=0,0,C5/B5) -> 11.55 | E5: =COUNTIFS(Takip!$C$2:$C$501,A5,Takip!$M$2:$M$501,">="&Ayarlar!$B$6) -> 10 | F5: =COUNTIFS(Takip!$C$2:$C$501,A5,Takip!$M$2:$M$501,">="&Ayarlar!$B$7) -> 3 | G5: =IF(F5>=Ayarlar!$B$8,"▲ ALARM",IF(E5>0,"● Planla","✓")) -> ● Planla | H5: =COUNTIFS(Takip!$C$2:$C$501,A5,Takip!$R$2:$R$501,"Evet") -> 3 | I5: =SUMIFS(Takip!$P$2:$P$501,Takip!$C$2:$C$501,A5) -> 46 | J5: =SUMIFS(Veri_Onceki!$H:$H,Veri_Onceki!$C:$C,A5) -> 203 | K5: =C5-J5 -> 28 | L5: =COUNTIFS(Takip!$C$2:$C$501,A5,Takip!$S$2:$S$501,"Yeni personel") -> 1 | M5: =COUNTIFS(Veri_Onceki!$C:$C,A5,Veri_Onceki!$I:$I,1) -> 1
A6: =Ayarlar!A17 -> Bölge 3 | B6: =COUNTIFS(Takip!$C$2:$C$501,A6,Takip!$G$2:$G$501,1) -> 20 | C6: =SUMIFS(Takip!$M$2:$M$501,Takip!$C$2:$C$501,A6) -> 265 | D6: =IF(B6=0,0,C6/B6) -> 13.25 | E6: =COUNTIFS(Takip!$C$2:$C$501,A6,Takip!$M$2:$M$501,">="&Ayarlar!$B$6) -> 12 | F6: =COUNTIFS(Takip!$C$2:$C$501,A6,Takip!$M$2:$M$501,">="&Ayarlar!$B$7) -> 4 | G6: =IF(F6>=Ayarlar!$B$8,"▲ ALARM",IF(E6>0,"● Planla","✓")) -> ● Planla | H6: =COUNTIFS(Takip!$C$2:$C$501,A6,Takip!$R$2:$R$501,"Evet") -> 4 | I6: =SUMIFS(Takip!$P$2:$P$501,Takip!$C$2:$C$501,A6) -> 59 | J6: =SUMIFS(Veri_Onceki!$H:$H,Veri_Onceki!$C:$C,A6) -> 314 | K6: =C6-J6 -> -49 | L6: =COUNTIFS(Takip!$C$2:$C$501,A6,Takip!$S$2:$S$501,"Yeni personel") -> 1 | M6: =COUNTIFS(Veri_Onceki!$C:$C,A6,Veri_Onceki!$I:$I,1) -> 1
A7: =Ayarlar!A18 -> Bölge 4 | B7: =COUNTIFS(Takip!$C$2:$C$501,A7,Takip!$G$2:$G$501,1) -> 23 | C7: =SUMIFS(Takip!$M$2:$M$501,Takip!$C$2:$C$501,A7) -> 238 | D7: =IF(B7=0,0,C7/B7) -> 10.347826 | E7: =COUNTIFS(Takip!$C$2:$C$501,A7,Takip!$M$2:$M$501,">="&Ayarlar!$B$6) -> 10 | F7: =COUNTIFS(Takip!$C$2:$C$501,A7,Takip!$M$2:$M$501,">="&Ayarlar!$B$7) -> 3 | G7: =IF(F7>=Ayarlar!$B$8,"▲ ALARM",IF(E7>0,"● Planla","✓")) -> ● Planla | H7: =COUNTIFS(Takip!$C$2:$C$501,A7,Takip!$R$2:$R$501,"Evet") -> 1 | I7: =SUMIFS(Takip!$P$2:$P$501,Takip!$C$2:$C$501,A7) -> 56 | J7: =SUMIFS(Veri_Onceki!$H:$H,Veri_Onceki!$C:$C,A7) -> 280 | K7: =C7-J7 -> -42 | L7: =COUNTIFS(Takip!$C$2:$C$501,A7,Takip!$S$2:$S$501,"Yeni personel") -> 1 | M7: =COUNTIFS(Veri_Onceki!$C:$C,A7,Veri_Onceki!$I:$I,1) -> 0
A8: =Ayarlar!A19 -> Bölge 5 | B8: =COUNTIFS(Takip!$C$2:$C$501,A8,Takip!$G$2:$G$501,1) -> 24 | C8: =SUMIFS(Takip!$M$2:$M$501,Takip!$C$2:$C$501,A8) -> 370 | D8: =IF(B8=0,0,C8/B8) -> 15.416667 | E8: =COUNTIFS(Takip!$C$2:$C$501,A8,Takip!$M$2:$M$501,">="&Ayarlar!$B$6) -> 13 | F8: =COUNTIFS(Takip!$C$2:$C$501,A8,Takip!$M$2:$M$501,">="&Ayarlar!$B$7) -> 6 | G8: =IF(F8>=Ayarlar!$B$8,"▲ ALARM",IF(E8>0,"● Planla","✓")) -> ▲ ALARM | H8: =COUNTIFS(Takip!$C$2:$C$501,A8,Takip!$R$2:$R$501,"Evet") -> 2 | I8: =SUMIFS(Takip!$P$2:$P$501,Takip!$C$2:$C$501,A8) -> 48 | J8: =SUMIFS(Veri_Onceki!$H:$H,Veri_Onceki!$C:$C,A8) -> 364 | K8: =C8-J8 -> 6 | L8: =COUNTIFS(Takip!$C$2:$C$501,A8,Takip!$S$2:$S$501,"Yeni personel") -> 0 | M8: =COUNTIFS(Veri_Onceki!$C:$C,A8,Veri_Onceki!$I:$I,1) -> 0
A9: =Ayarlar!A20 -> Bölge 6 | B9: =COUNTIFS(Takip!$C$2:$C$501,A9,Takip!$G$2:$G$501,1) -> 27 | C9: =SUMIFS(Takip!$M$2:$M$501,Takip!$C$2:$C$501,A9) -> 392 | D9: =IF(B9=0,0,C9/B9) -> 14.518519 | E9: =COUNTIFS(Takip!$C$2:$C$501,A9,Takip!$M$2:$M$501,">="&Ayarlar!$B$6) -> 16 | F9: =COUNTIFS(Takip!$C$2:$C$501,A9,Takip!$M$2:$M$501,">="&Ayarlar!$B$7) -> 7 | G9: =IF(F9>=Ayarlar!$B$8,"▲ ALARM",IF(E9>0,"● Planla","✓")) -> ▲ ALARM | H9: =COUNTIFS(Takip!$C$2:$C$501,A9,Takip!$R$2:$R$501,"Evet") -> 1 | I9: =SUMIFS(Takip!$P$2:$P$501,Takip!$C$2:$C$501,A9) -> 63 | J9: =SUMIFS(Veri_Onceki!$H:$H,Veri_Onceki!$C:$C,A9) -> 375 | K9: =C9-J9 -> 17 | L9: =COUNTIFS(Takip!$C$2:$C$501,A9,Takip!$S$2:$S$501,"Yeni personel") -> 0 | M9: =COUNTIFS(Veri_Onceki!$C:$C,A9,Veri_Onceki!$I:$I,1) -> 2
A10: TOPLAM | B10: =SUM(B4:B9) -> 137 | C10: =SUM(C4:C9) -> 1731 | D10: =IF(B10=0,0,C10/B10) -> 12.635036 | E10: =SUM(E4:E9) -> 69 | F10: =SUM(F4:F9) -> 26 | G10: =COUNTIF(G4:G9,"▲ ALARM")&" bölgede alarm" -> 2 bölgede alarm | H10: =SUM(H4:H9) -> 14 | I10: =SUM(I4:I9) -> 344 | J10: =SUM(J4:J9) -> 1803 | K10: =SUM(K4:K9) -> -72 | L10: =SUM(L4:L9) -> 4 | M10: =SUM(M4:M9) -> 4
A12: Kapsam dışı ayıklanan kayıt: | C12: =COUNTIF(Takip!$G$2:$G$501,0) -> 52
A13: Kontrol edilmesi gereken kayıt: | C13: =COUNTIF(Takip!$S$2:$S$501,"Kontrol et") -> 1

Sheet Liste_14_Gun
A1: ="14 gün ve üzeri izin bakiyesi — "&Ayarlar!$B$11&" · data tarihi "&TEXT(Ayarlar!$B$3,"dd.mm.yyyy") -> 14 gün ve üzeri izin bakiyesi — Tümü · data tarihi 14.09.2026
A3: Bilgilendirme taslağı:
A4: ="Merhaba, "&TEXT(Ayarlar!$B$3,"dd.mm.yyyy")&" tarihli dataya göre "&IF(Ayarlar!$B$11="Tümü","takip edilen bölgelerde ",Ayarlar!$B$11&" bölgesinde ")&COUNT(C8:C207)&" personelin "&Ayarlar!$B$6&" gün ve üzeri kullanılmamış izni bulunuyor; bunların "&COUNTIF(H8:H207,"ALARM")&" tanesi "&Ayarlar!$B$7&" günü aşıyor. Liste aşağıdadır; izin planlamasının yapılmasını rica ederim." -> Merhaba, 14.09.2026 tarihli dataya göre takip edilen bölgelerde 69 personelin 14 gün ve üzeri kullanılmamış izni bulunuyor; bunların 26 tanesi 20 günü aşıyor. Liste aşağıdadır; izin planlamasının yapılmasını rica ederim.
A7: Sıra | B7: Satır | C7: Biriken İzin | D7: Bölge | E7: Mağaza | F7: Sicil No | G7: Ad Soyad | H7: Durum | I7: Sonraki Hak Ediş | J7: Hak Ediş Yaklaşıyor
A8: =IF(B8="","",1) -> 1 | B8: =IFERROR(MATCH(LARGE(Takip!$T$2:$T$501,1),Takip!$T$2:$T$501,0)+1,"") -> 134 | C8: =IF(B8="","",INDEX(Takip!$M:$M,B8)) -> 28 | D8: =IF($B8="","",INDEX(Takip!$C:$C,$B8)) -> Bölge 6 | E8: =IF($B8="","",INDEX(Takip!$D:$D,$B8)) -> Mağaza 6D | F8: =IF($B8="","",INDEX(Takip!$A:$A,$B8)) -> S10133 | G8: =IF($B8="","",INDEX(Takip!$B:$B,$B8)) -> Mert Doğan | H8: =IF($B8="","",INDEX(Takip!$Q:$Q,$B8)) -> ALARM | I8: =IF($B8="","",INDEX(Takip!$K:$K,$B8)) -> 46564 | J8: =IF($B8="","",INDEX(Takip!$R:$R,$B8))
A9: =IF(B9="","",2) -> 2 | B9: =IFERROR(MATCH(LARGE(Takip!$T$2:$T$501,2),Takip!$T$2:$T$501,0)+1,"") -> 110 | C9: =IF(B9="","",INDEX(Takip!$M:$M,B9)) -> 28 | D9: =IF($B9="","",INDEX(Takip!$C:$C,$B9)) -> Bölge 6 | E9: =IF($B9="","",INDEX(Takip!$D:$D,$B9)) -> Mağaza 6A | F9: =IF($B9="","",INDEX(Takip!$A:$A,$B9)) -> S10109 | G9: =IF($B9="","",INDEX(Takip!$B:$B,$B9)) -> Melis Özdemir | H9: =IF($B9="","",INDEX(Takip!$Q:$Q,$B9)) -> ALARM | I9: =IF($B9="","",INDEX(Takip!$K:$K,$B9)) -> 46602 | J9: =IF($B9="","",INDEX(Takip!$R:$R,$B9))
A10: =IF(B10="","",3) -> 3 | B10: =IFERROR(MATCH(LARGE(Takip!$T$2:$T$501,3),Takip!$T$2:$T$501,0)+1,"") -> 108 | C10: =IF(B10="","",INDEX(Takip!$M:$M,B10)) -> 28 | D10: =IF($B10="","",INDEX(Takip!$C:$C,$B10)) -> Bölge 6 | E10: =IF($B10="","",INDEX(Takip!$D:$D,$B10)) -> Mağaza 6A | F10: =IF($B10="","",INDEX(Takip!$A:$A,$B10)) -> S10107 | G10: =IF($B10="","",INDEX(Takip!$B:$B,$B10)) -> Tolga Şahin | H10: =IF($B10="","",INDEX(Takip!$Q:$Q,$B10)) -> ALARM | I10: =IF($B10="","",INDEX(Takip!$K:$K,$B10)) -> 46602 | J10: =IF($B10="","",INDEX(Takip!$R:$R,$B10))
A11: =IF(B11="","",4) -> 4 | B11: =IFERROR(MATCH(LARGE(Takip!$T$2:$T$501,4),Takip!$T$2:$T$501,0)+1,"") -> 106 | C11: =IF(B11="","",INDEX(Takip!$M:$M,B11)) -> 28 | D11: =IF($B11="","",INDEX(Takip!$C:$C,$B11)) -> Bölge 5 | E11: =IF($B11="","",INDEX(Takip!$D:$D,$B11)) -> Mağaza 5D | F11: =IF($B11="","",INDEX(Takip!$A:$A,$B11)) -> S10105 | G11: =IF($B11="","",INDEX(Takip!$B:$B,$B11)) -> Kaan Aydın | H11: =IF($B11="","",INDEX(Takip!$Q:$Q,$B11)) -> ALARM | I11: =IF($B11="","",INDEX(Takip!$K:$K,$B11)) -> 46487 | J11: =IF($B11="","",INDEX(Takip!$R:$R,$B11))
A12: =IF(B12="","",5) -> 5 | B12: =IFERROR(MATCH(LARGE(Takip!$T$2:$T$501,5),Takip!$T$2:$T$501,0)+1,"") -> 100 | C12: =IF(B12="","",INDEX(Takip!$M:$M,B12)) -> 28 | D12: =IF($B12="","",INDEX(Takip!$C:$C,$B12)) -> Bölge 5 | E12: =IF($B12="","",INDEX(Takip!$D:$D,$B12)) -> Mağaza 5C | F12: =IF($B12="","",INDEX(Takip!$A:$A,$B12)) -> S10099 | G12: =IF($B12="","",INDEX(Takip!$B:$B,$B12)) -> Onur Çelik | H12: =IF($B12="","",INDEX(Takip!$Q:$Q,$B12)) -> ALARM | I12: =IF($B12="","",INDEX(Takip!$K:$K,$B12)) -> 46620 | J12: =IF($B12="","",INDEX(Takip!$R:$R,$B12))
A13: =IF(B13="","",6) -> 6 | B13: =IFERROR(MATCH(LARGE(Takip!$T$2:$T$501,6),Takip!$T$2:$T$501,0)+1,"") -> 85 | C13: =IF(B13="","",INDEX(Takip!$M:$M,B13)) -> 28 | D13: =IF($B13="","",INDEX(Takip!$C:$C,$B13)) -> Bölge 5 | E13: =IF($B13="","",INDEX(Takip!$D:$D,$B13)) -> Mağaza 5A | F13: =IF($B13="","",INDEX(Takip!$A:$A,$B13)) -> S10084 | G13: =IF($B13="","",INDEX(Takip!$B:$B,$B13)) -> Elif Çelik | H13: =IF($B13="","",INDEX(Takip!$Q:$Q,$B13)) -> ALARM | I13: =IF($B13="","",INDEX(Takip!$K:$K,$B13)) -> 46526 | J13: =IF($B13="","",INDEX(Takip!$R:$R,$B13))
A14: =IF(B14="","",7) -> 7 | B14: =IFERROR(MATCH(LARGE(Takip!$T$2:$T$501,7),Takip!$T$2:$T$501,0)+1,"") -> 81 | C14: =IF(B14="","",INDEX(Takip!$M:$M,B14)) -> 28 | D14: =IF($B14="","",INDEX(Takip!$C:$C,$B14)) -> Bölge 4 | E14: =IF($B14="","",INDEX(Takip!$D:$D,$B14)) -> Mağaza 4C | F14: =IF($B14="","",INDEX(Takip!$A:$A,$B14)) -> S10080 | G14: =IF($B14="","",INDEX(Takip!$B:$B,$B14)) -> Buse Yılmaz | H14: =IF($B14="","",INDEX(Takip!$Q:$Q,$B14)) -> ALARM | I14: =IF($B14="","",INDEX(Takip!$K:$K,$B14)) -> 46484 | J14: =IF($B14="","",INDEX(Takip!$R:$R,$B14))
A15: =IF(B15="","",8) -> 8 | B15: =IFERROR(MATCH(LARGE(Takip!$T$2:$T$501,8),Takip!$T$2:$T$501,0)+1,"") -> 53 | C15: =IF(B15="","",INDEX(Takip!$M:$M,B15)) -> 28 | D15: =IF($B15="","",INDEX(Takip!$C:$C,$B15)) -> Bölge 3 | E15: =IF($B15="","",INDEX(Takip!$D:$D,$B15)) -> Mağaza 3B | F15: =IF($B15="","",INDEX(Takip!$A:$A,$B15)) -> S10052 | G15: =IF($B15="","",INDEX(Takip!$B:$B,$B15)) -> Burak Aydın | H15: =IF($B15="","",INDEX(Takip!$Q:$Q,$B15)) -> ALARM | I15: =IF($B15="","",INDEX(Takip!$K:$K,$B15)) -> 46373 | J15: =IF($B15="","",INDEX(Takip!$R:$R,$B15))
A16: =IF(B16="","",9) -> 9 | B16: =IFERROR(MATCH(LARGE(Takip!$T$2:$T$501,9),Takip!$T$2:$T$501,0)+1,"") -> 47 | C16: =IF(B16="","",INDEX(Takip!$M:$M,B16)) -> 28 | D16: =IF($B16="","",INDEX(Takip!$C:$C,$B16)) -> Bölge 3 | E16: =IF($B16="","",INDEX(Takip!$D:$D,$B16)) -> Mağaza 3A | F16: =IF($B16="","",INDEX(Takip!$A:$A,$B16)) -> S10046 | G16: =IF($B16="","",INDEX(Takip!$B:$B,$B16)) -> Oğuz Aydın | H16: =IF($B16="","",INDEX(Takip!$Q:$Q,$B16)) -> ALARM | I16: =IF($B16="","",INDEX(Takip!$K:$K,$B16)) -> 46345 | J16: =IF($B16="","",INDEX(Takip!$R:$R,$B16))
A17: =IF(B17="","",10) -> 10 | B17: =IFERROR(MATCH(LARGE(Takip!$T$2:$T$501,10),Takip!$T$2:$T$501,0)+1,"") -> 40 | C17: =IF(B17="","",INDEX(Takip!$M:$M,B17)) -> 28 | D17: =IF($B17="","",INDEX(Takip!$C:$C,$B17)) -> Bölge 2 | E17: =IF($B17="","",INDEX(Takip!$D:$D,$B17)) -> Mağaza 2C | F17: =IF($B17="","",INDEX(Takip!$A:$A,$B17)) -> S10039 | G17: =IF($B17="","",INDEX(Takip!$B:$B,$B17)) -> Elif Aydın | H17: =IF($B17="","",INDEX(Takip!$Q:$Q,$B17)) -> ALARM | I17: =IF($B17="","",INDEX(Takip!$K:$K,$B17)) -> 46419 | J17: =IF($B17="","",INDEX(Takip!$R:$R,$B17))
A18: =IF(B18="","",11) -> 11 | B18: =IFERROR(MATCH(LARGE(Takip!$T$2:$T$501,11),Takip!$T$2:$T$501,0)+1,"") -> 33 | C18: =IF(B18="","",INDEX(Takip!$M:$M,B18)) -> 28 | D18: =IF($B18="","",INDEX(Takip!$C:$C,$B18)) -> Bölge 2 | E18: =IF($B18="","",INDEX(Takip!$D:$D,$B18)) -> Mağaza 2B | F18: =IF($B18="","",INDEX(Takip!$A:$A,$B18)) -> S10032 | G18: =IF($B18="","",INDEX(Takip!$B:$B,$B18)) -> Melis Kurt | H18: =IF($B18="","",INDEX(Takip!$Q:$Q,$B18)) -> ALARM | I18: =IF($B18="","",INDEX(Takip!$K:$K,$B18)) -> 46395 | J18: =IF($B18="","",INDEX(Takip!$R:$R,$B18))
A19: =IF(B19="","",12) -> 12 | B19: =IFERROR(MATCH(LARGE(Takip!$T$2:$T$501,12),Takip!$T$2:$T$501,0)+1,"") -> 23 | C19: =IF(B19="","",INDEX(Takip!$M:$M,B19)) -> 28 | D19: =IF($B19="","",INDEX(Takip!$C:$C,$B19)) -> Bölge 1 | E19: =IF($B19="","",INDEX(Takip!$D:$D,$B19)) -> Mağaza 1C | F19: =IF($B19="","",INDEX(Takip!$A:$A,$B19)) -> S10022 | G19: =IF($B19="","",INDEX(Takip!$B:$B,$B19)) -> Emre Doğan | H19: =IF($B19="","",INDEX(Takip!$Q:$Q,$B19)) -> ALARM | I19: =IF($B19="","",INDEX(Takip!$K:$K,$B19)) -> 46447 | J19: =IF($B19="","",INDEX(Takip!$R:$R,$B19))
A20: =IF(B20="","",13) -> 13 | B20: =IFERROR(MATCH(LARGE(Takip!$T$2:$T$501,13),Takip!$T$2:$T$501,0)+1,"") -> 17 | C20: =IF(B20="","",INDEX(Takip!$M:$M,B20)) -> 28 | D20: =IF($B20="","",INDEX(Takip!$C:$C,$B20)) -> Bölge 1 | E20: =IF($B20="","",INDEX(Takip!$D:$D,$B20)) -> Mağaza 1C | F20: =IF($B20="","",INDEX(Takip!$A:$A,$B20)) -> S10016 | G20: =IF($B20="","",INDEX(Takip!$B:$B,$B20)) -> Ece Çelik | H20: =IF($B20="","",INDEX(Takip!$Q:$Q,$B20)) -> ALARM | I20: =IF($B20="","",INDEX(Takip!$K:$K,$B20)) -> 46576 | J20: =IF($B20="","",INDEX(Takip!$R:$R,$B20))
A21: =IF(B21="","",14) -> 14 | B21: =IFERROR(MATCH(LARGE(Takip!$T$2:$T$501,14),Takip!$T$2:$T$501,0)+1,"") -> 12 | C21: =IF(B21="","",INDEX(Takip!$M:$M,B21)) -> 28 | D21: =IF($B21="","",INDEX(Takip!$C:$C,$B21)) -> Bölge 1 | E21: =IF($B21="","",INDEX(Takip!$D:$D,$B21)) -> Mağaza 1B | F21: =IF($B21="","",INDEX(Takip!$A:$A,$B21)) -> S10011 | G21: =IF($B21="","",INDEX(Takip!$B:$B,$B21)) -> Ece Aslan | H21: =IF($B21="","",INDEX(Takip!$Q:$Q,$B21)) -> ALARM | I21: =IF($B21="","",INDEX(Takip!$K:$K,$B21)) -> 46468 | J21: =IF($B21="","",INDEX(Takip!$R:$R,$B21))
A22: =IF(B22="","",15) -> 15 | B22: =IFERROR(MATCH(LARGE(Takip!$T$2:$T$501,15),Takip!$T$2:$T$501,0)+1,"") -> 118 | C22: =IF(B22="","",INDEX(Takip!$M:$M,B22)) -> 24 | D22: =IF($B22="","",INDEX(Takip!$C:$C,$B22)) -> Bölge 6 | E22: =IF($B22="","",INDEX(Takip!$D:$D,$B22)) -> Mağaza 6B | F22: =IF($B22="","",INDEX(Takip!$A:$A,$B22)) -> S10117 | G22: =IF($B22="","",INDEX(Takip!$B:$B,$B22)) -> Gizem Şahin | H22: =IF($B22="","",INDEX(Takip!$Q:$Q,$B22)) -> ALARM | I22: =IF($B22="","",INDEX(Takip!$K:$K,$B22)) -> 46639 | J22: =IF($B22="","",INDEX(Takip!$R:$R,$B22))
A23: =IF(B23="","",16) -> 16 | B23: =IFERROR(MATCH(LARGE(Takip!$T$2:$T$501,16),Takip!$T$2:$T$501,0)+1,"") -> 107 | C23: =IF(B23="","",INDEX(Takip!$M:$M,B23)) -> 24 | D23: =IF($B23="","",INDEX(Takip!$C:$C,$B23)) -> Bölge 5 | E23: =IF($B23="","",INDEX(Takip!$D:$D,$B23)) -> Mağaza 5D | F23: =IF($B23="","",INDEX(Takip!$A:$A,$B23)) -> S10106 | G23: =IF($B23="","",INDEX(Takip!$B:$B,$B23)) -> Can Yıldız | H23: =IF($B23="","",INDEX(Takip!$Q:$Q,$B23)) -> ALARM | I23: =IF($B23="","",INDEX(Takip!$K:$K,$B23)) -> 46310 | J23: =IF($B23="","",INDEX(Takip!$R:$R,$B23)) -> Evet
A24: =IF(B24="","",17) -> 17 | B24: =IFERROR(MATCH(LARGE(Takip!$T$2:$T$501,17),Takip!$T$2:$T$501,0)+1,"") -> 94 | C24: =IF(B24="","",INDEX(Takip!$M:$M,B24)) -> 24 | D24: =IF($B24="","",INDEX(Takip!$C:$C,$B24)) -> Bölge 5 | E24: =IF($B24="","",INDEX(Takip!$D:$D,$B24)) -> Mağaza 5B | F24: =IF($B24="","",INDEX(Takip!$A:$A,$B24)) -> S10093 | G24: =IF($B24="","",INDEX(Takip!$B:$B,$B24)) -> Serkan Öztürk | H24: =IF($B24="","",INDEX(Takip!$Q:$Q,$B24)) -> ALARM | I24: =IF($B24="","",INDEX(Takip!$K:$K,$B24)) -> 46345 | J24: =IF($B24="","",INDEX(Takip!$R:$R,$B24))
A25: =IF(B25="","",18) -> 18 | B25: =IFERROR(MATCH(LARGE(Takip!$T$2:$T$501,18),Takip!$T$2:$T$501,0)+1,"") -> 90 | C25: =IF(B25="","",INDEX(Takip!$M:$M,B25)) -> 24 | D25: =IF($B25="","",INDEX(Takip!$C:$C,$B25)) -> Bölge 5 | E25: =IF($B25="","",INDEX(Takip!$D:$D,$B25)) -> Mağaza 5B | F25: =IF($B25="","",INDEX(Takip!$A:$A,$B25)) -> S10089 | G25: =IF($B25="","",INDEX(Takip!$B:$B,$B25)) -> Burak Özdemir | H25: =IF($B25="","",INDEX(Takip!$Q:$Q,$B25)) -> ALARM | I25: =IF($B25="","",INDEX(Takip!$K:$K,$B25)) -> 46474 | J25: =IF($B25="","",INDEX(Takip!$R:$R,$B25))
A26: =IF(B26="","",19) -> 19 | B26: =IFERROR(MATCH(LARGE(Takip!$T$2:$T$501,19),Takip!$T$2:$T$501,0)+1,"") -> 66 | C26: =IF(B26="","",INDEX(Takip!$M:$M,B26)) -> 24 | D26: =IF($B26="","",INDEX(Takip!$C:$C,$B26)) -> Bölge 4 | E26: =IF($B26="","",INDEX(Takip!$D:$D,$B26)) -> Mağaza 4A | F26: =IF($B26="","",INDEX(Takip!$A:$A,$B26)) -> S10065 | G26: =IF($B26="","",INDEX(Takip!$B:$B,$B26)) -> Cem Kaya | H26: =IF($B26="","",INDEX(Takip!$Q:$Q,$B26)) -> ALARM | I26: =IF($B26="","",INDEX(Takip!$K:$K,$B26)) -> 46493 | J26: =IF($B26="","",INDEX(Takip!$R:$R,$B26))
A27: =IF(B27="","",20) -> 20 | B27: =IFERROR(MATCH(LARGE(Takip!$T$2:$T$501,20),Takip!$T$2:$T$501,0)+1,"") -> 64 | C27: =IF(B27="","",INDEX(Takip!$M:$M,B27)) -> 24 | D27: =IF($B27="","",INDEX(Takip!$C:$C,$B27)) -> Bölge 4 | E27: =IF($B27="","",INDEX(Takip!$D:$D,$B27)) -> Mağaza 4A | F27: =IF($B27="","",INDEX(Takip!$A:$A,$B27)) -> S10063 | G27: =IF($B27="","",INDEX(Takip!$B:$B,$B27)) -> Mert Çelik | H27: =IF($B27="","",INDEX(Takip!$Q:$Q,$B27)) -> ALARM | I27: =IF($B27="","",INDEX(Takip!$K:$K,$B27)) -> 46479 | J27: =IF($B27="","",INDEX(Takip!$R:$R,$B27))
A28: =IF(B28="","",21) -> 21 | B28: =IFERROR(MATCH(LARGE(Takip!$T$2:$T$501,21),Takip!$T$2:$T$501,0)+1,"") -> 57 | C28: =IF(B28="","",INDEX(Takip!$M:$M,B28)) -> 24 | D28: =IF($B28="","",INDEX(Takip!$C:$C,$B28)) -> Bölge 3 | E28: =IF($B28="","",INDEX(Takip!$D:$D,$B28)) -> Mağaza 3C | F28: =IF($B28="","",INDEX(Takip!$A:$A,$B28)) -> S10056 | G28: =IF($B28="","",INDEX(Takip!$B:$B,$B28)) -> Melis Yıldız | H28: =IF($B28="","",INDEX(Takip!$Q:$Q,$B28)) -> ALARM | I28: =IF($B28="","",INDEX(Takip!$K:$K,$B28)) -> 46466 | J28: =IF($B28="","",INDEX(Takip!$R:$R,$B28))
A29: =IF(B29="","",22) -> 22 | B29: =IFERROR(MATCH(LARGE(Takip!$T$2:$T$501,22),Takip!$T$2:$T$501,0)+1,"") -> 56 | C29: =IF(B29="","",INDEX(Takip!$M:$M,B29)) -> 24 | D29: =IF($B29="","",INDEX(Takip!$C:$C,$B29)) -> Bölge 3 | E29: =IF($B29="","",INDEX(Takip!$D:$D,$B29)) -> Mağaza 3C | F29: =IF($B29="","",INDEX(Takip!$A:$A,$B29)) -> S10055 | G29: =IF($B29="","",INDEX(Takip!$B:$B,$B29)) -> Onur Yılmaz | H29: =IF($B29="","",INDEX(Takip!$Q:$Q,$B29)) -> ALARM | I29: =IF($B29="","",INDEX(Takip!$K:$K,$B29)) -> 46520 | J29: =IF($B29="","",INDEX(Takip!$R:$R,$B29))
A30: =IF(B30="","",23) -> 23 | B30: =IFERROR(MATCH(LARGE(Takip!$T$2:$T$501,23),Takip!$T$2:$T$501,0)+1,"") -> 129 | C30: =IF(B30="","",INDEX(Takip!$M:$M,B30)) -> 21 | D30: =IF($B30="","",INDEX(Takip!$C:$C,$B30)) -> Bölge 6 | E30: =IF($B30="","",INDEX(Takip!$D:$D,$B30)) -> Mağaza 6D | F30: =IF($B30="","",INDEX(Takip!$A:$A,$B30)) -> S10128 | G30: =IF($B30="","",INDEX(Takip!$B:$B,$B30)) -> Melis Kaya | H30: =IF($B30="","",INDEX(Takip!$Q:$Q,$B30)) -> ALARM | I30: =IF($B30="","",INDEX(Takip!$K:$K,$B30)) -> 46372 | J30: =IF($B30="","",INDEX(Takip!$R:$R,$B30))
A31: =IF(B31="","",24) -> 24 | B31: =IFERROR(MATCH(LARGE(Takip!$T$2:$T$501,24),Takip!$T$2:$T$501,0)+1,"") -> 120 | C31: =IF(B31="","",INDEX(Takip!$M:$M,B31)) -> 21 | D31: =IF($B31="","",INDEX(Takip!$C:$C,$B31)) -> Bölge 6 | E31: =IF($B31="","",INDEX(Takip!$D:$D,$B31)) -> Mağaza 6B | F31: =IF($B31="","",INDEX(Takip!$A:$A,$B31)) -> S10119 | G31: =IF($B31="","",INDEX(Takip!$B:$B,$B31)) -> Can Kurt | H31: =IF($B31="","",INDEX(Takip!$Q:$Q,$B31)) -> ALARM | I31: =IF($B31="","",INDEX(Takip!$K:$K,$B31)) -> 46370 | J31: =IF($B31="","",INDEX(Takip!$R:$R,$B31))
A32: =IF(B32="","",25) -> 25 | B32: =IFERROR(MATCH(LARGE(Takip!$T$2:$T$501,25),Takip!$T$2:$T$501,0)+1,"") -> 119 | C32: =IF(B32="","",INDEX(Takip!$M:$M,B32)) -> 21 | D32: =IF($B32="","",INDEX(Takip!$C:$C,$B32)) -> Bölge 6 | E32: =IF($B32="","",INDEX(Takip!$D:$D,$B32)) -> Mağaza 6B | F32: =IF($B32="","",INDEX(Takip!$A:$A,$B32)) -> S10118 | G32: =IF($B32="","",INDEX(Takip!$B:$B,$B32)) -> Ayşe Öztürk | H32: =IF($B32="","",INDEX(Takip!$Q:$Q,$B32)) -> ALARM | I32: =IF($B32="","",INDEX(Takip!$K:$K,$B32)) -> 46298 | J32: =IF($B32="","",INDEX(Takip!$R:$R,$B32)) -> Evet
A33: =IF(B33="","",26) -> 26 | B33: =IFERROR(MATCH(LARGE(Takip!$T$2:$T$501,26),Takip!$T$2:$T$501,0)+1,"") -> 25 | C33: =IF(B33="","",INDEX(Takip!$M:$M,B33)) -> 21 | D33: =IF($B33="","",INDEX(Takip!$C:$C,$B33)) -> Bölge 2 | E33: =IF($B33="","",INDEX(Takip!$D:$D,$B33)) -> Mağaza 2A | F33: =IF($B33="","",INDEX(Takip!$A:$A,$B33)) -> S10024 | G33: =IF($B33="","",INDEX(Takip!$B:$B,$B33)) -> Buse Kaya | H33: =IF($B33="","",INDEX(Takip!$Q:$Q,$B33)) -> ALARM | I33: =IF($B33="","",INDEX(Takip!$K:$K,$B33)) -> 46380 | J33: =IF($B33="","",INDEX(Takip!$R:$R,$B33))
A34: =IF(B34="","",27) -> 27 | B34: =IFERROR(MATCH(LARGE(Takip!$T$2:$T$501,27),Takip!$T$2:$T$501,0)+1,"") -> 127 | C34: =IF(B34="","",INDEX(Takip!$M:$M,B34)) -> 19 | D34: =IF($B34="","",INDEX(Takip!$C:$C,$B34)) -> Bölge 6 | E34: =IF($B34="","",INDEX(Takip!$D:$D,$B34)) -> Mağaza 6D | F34: =IF($B34="","",INDEX(Takip!$A:$A,$B34)) -> S10126 | G34: =IF($B34="","",INDEX(Takip!$B:$B,$B34)) -> Umut Aydın | H34: =IF($B34="","",INDEX(Takip!$Q:$Q,$B34)) -> Planla | I34: =IF($B34="","",INDEX(Takip!$K:$K,$B34)) -> 46594 | J34: =IF($B34="","",INDEX(Takip!$R:$R,$B34))
A35: =IF(B35="","",28) -> 28 | B35: =IFERROR(MATCH(LARGE(Takip!$T$2:$T$501,28),Takip!$T$2:$T$501,0)+1,"") -> 123 | C35: =IF(B35="","",INDEX(Takip!$M:$M,B35)) -> 19 | D35: =IF($B35="","",INDEX(Takip!$C:$C,$B35)) -> Bölge 6 | E35: =IF($B35="","",INDEX(Takip!$D:$D,$B35)) -> Mağaza 6C | F35: =IF($B35="","",INDEX(Takip!$A:$A,$B35)) -> S10122 | G35: =IF($B35="","",INDEX(Takip!$B:$B,$B35)) -> Can Öztürk | H35: =IF($B35="","",INDEX(Takip!$Q:$Q,$B35)) -> Planla | I35: =IF($B35="","",INDEX(Takip!$K:$K,$B35)) -> 46644 | J35: =IF($B35="","",INDEX(Takip!$R:$R,$B35))
A36: =IF(B36="","",29) -> 29 | B36: =IFERROR(MATCH(LARGE(Takip!$T$2:$T$501,29),Takip!$T$2:$T$501,0)+1,"") -> 121 | C36: =IF(B36="","",INDEX(Takip!$M:$M,B36)) -> 19 | D36: =IF($B36="","",INDEX(Takip!$C:$C,$B36)) -> Bölge 6 | E36: =IF($B36="","",INDEX(Takip!$D:$D,$B36)) -> Mağaza 6C | F36: =IF($B36="","",INDEX(Takip!$A:$A,$B36)) -> S10120 | G36: =IF($B36="","",INDEX(Takip!$B:$B,$B36)) -> Umut Arslan | H36: =IF($B36="","",INDEX(Takip!$Q:$Q,$B36)) -> Planla | I36: =IF($B36="","",INDEX(Takip!$K:$K,$B36)) -> 46366 | J36: =IF($B36="","",INDEX(Takip!$R:$R,$B36))
A37: =IF(B37="","",30) -> 30 | B37: =IFERROR(MATCH(LARGE(Takip!$T$2:$T$501,30),Takip!$T$2:$T$501,0)+1,"") -> 113 | C37: =IF(B37="","",INDEX(Takip!$M:$M,B37)) -> 19 | D37: =IF($B37="","",INDEX(Takip!$C:$C,$B37)) -> Bölge 6 | E37: =IF($B37="","",INDEX(Takip!$D:$D,$B37)) -> Mağaza 6B | F37: =IF($B37="","",INDEX(Takip!$A:$A,$B37)) -> S10112 | G37: =IF($B37="","",INDEX(Takip!$B:$B,$B37)) -> Deniz Öztürk | H37: =IF($B37="","",INDEX(Takip!$Q:$Q,$B37)) -> Planla | I37: =IF($B37="","",INDEX(Takip!$K:$K,$B37)) -> 46556 | J37: =IF($B37="","",INDEX(Takip!$R:$R,$B37))
A38: =IF(B38="","",31) -> 31 | B38: =IFERROR(MATCH(LARGE(Takip!$T$2:$T$501,31),Takip!$T$2:$T$501,0)+1,"") -> 98 | C38: =IF(B38="","",INDEX(Takip!$M:$M,B38)) -> 19 | D38: =IF($B38="","",INDEX(Takip!$C:$C,$B38)) -> Bölge 5 | E38: =IF($B38="","",INDEX(Takip!$D:$D,$B38)) -> Mağaza 5C | F38: =IF($B38="","",INDEX(Takip!$A:$A,$B38)) -> S10097 | G38: =IF($B38="","",INDEX(Takip!$B:$B,$B38)) -> İrem Doğan | H38: =IF($B38="","",INDEX(Takip!$Q:$Q,$B38)) -> Planla | I38: =IF($B38="","",INDEX(Takip!$K:$K,$B38)) -> 46424 | J38: =IF($B38="","",INDEX(Takip!$R:$R,$B38))
A39: =IF(B39="","",32) -> 32 | B39: =IFERROR(MATCH(LARGE(Takip!$T$2:$T$501,32),Takip!$T$2:$T$501,0)+1,"") -> 95 | C39: =IF(B39="","",INDEX(Takip!$M:$M,B39)) -> 19 | D39: =IF($B39="","",INDEX(Takip!$C:$C,$B39)) -> Bölge 5 | E39: =IF($B39="","",INDEX(Takip!$D:$D,$B39)) -> Mağaza 5B | F39: =IF($B39="","",INDEX(Takip!$A:$A,$B39)) -> S10094 | G39: =IF($B39="","",INDEX(Takip!$B:$B,$B39)) -> Pınar Aydın | H39: =IF($B39="","",INDEX(Takip!$Q:$Q,$B39)) -> Planla | I39: =IF($B39="","",INDEX(Takip!$K:$K,$B39)) -> 46394 | J39: =IF($B39="","",INDEX(Takip!$R:$R,$B39))
A40: =IF(B40="","",33) -> 33 | B40: =IFERROR(MATCH(LARGE(Takip!$T$2:$T$501,33),Takip!$T$2:$T$501,0)+1,"") -> 92 | C40: =IF(B40="","",INDEX(Takip!$M:$M,B40)) -> 19 | D40: =IF($B40="","",INDEX(Takip!$C:$C,$B40)) -> Bölge 5 | E40: =IF($B40="","",INDEX(Takip!$D:$D,$B40)) -> Mağaza 5B | F40: =IF($B40="","",INDEX(Takip!$A:$A,$B40)) -> S10091 | G40: =IF($B40="","",INDEX(Takip!$B:$B,$B40)) -> Elif Doğan | H40: =IF($B40="","",INDEX(Takip!$Q:$Q,$B40)) -> Planla | I40: =IF($B40="","",INDEX(Takip!$K:$K,$B40)) -> 46604 | J40: =IF($B40="","",INDEX(Takip!$R:$R,$B40))
A41: =IF(B41="","",34) -> 34 | B41: =IFERROR(MATCH(LARGE(Takip!$T$2:$T$501,34),Takip!$T$2:$T$501,0)+1,"") -> 88 | C41: =IF(B41="","",INDEX(Takip!$M:$M,B41)) -> 19 | D41: =IF($B41="","",INDEX(Takip!$C:$C,$B41)) -> Bölge 5 | E41: =IF($B41="","",INDEX(Takip!$D:$D,$B41)) -> Mağaza 5A | F41: =IF($B41="","",INDEX(Takip!$A:$A,$B41)) -> S10087 | G41: =IF($B41="","",INDEX(Takip!$B:$B,$B41)) -> Mert Kılıç | H41: =IF($B41="","",INDEX(Takip!$Q:$Q,$B41)) -> Planla | I41: =IF($B41="","",INDEX(Takip!$K:$K,$B41)) -> 46642 | J41: =IF($B41="","",INDEX(Takip!$R:$R,$B41))
A42: =IF(B42="","",35) -> 35 | B42: =IFERROR(MATCH(LARGE(Takip!$T$2:$T$501,35),Takip!$T$2:$T$501,0)+1,"") -> 86 | C42: =IF(B42="","",INDEX(Takip!$M:$M,B42)) -> 19 | D42: =IF($B42="","",INDEX(Takip!$C:$C,$B42)) -> Bölge 5 | E42: =IF($B42="","",INDEX(Takip!$D:$D,$B42)) -> Mağaza 5A | F42: =IF($B42="","",INDEX(Takip!$A:$A,$B42)) -> S10085 | G42: =IF($B42="","",INDEX(Takip!$B:$B,$B42)) -> İrem Öztürk | H42: =IF($B42="","",INDEX(Takip!$Q:$Q,$B42)) -> Planla | I42: =IF($B42="","",INDEX(Takip!$K:$K,$B42)) -> 46520 | J42: =IF($B42="","",INDEX(Takip!$R:$R,$B42))
A43: =IF(B43="","",36) -> 36 | B43: =IFERROR(MATCH(LARGE(Takip!$T$2:$T$501,36),Takip!$T$2:$T$501,0)+1,"") -> 79 | C43: =IF(B43="","",INDEX(Takip!$M:$M,B43)) -> 19 | D43: =IF($B43="","",INDEX(Takip!$C:$C,$B43)) -> Bölge 4 | E43: =IF($B43="","",INDEX(Takip!$D:$D,$B43)) -> Mağaza 4C | F43: =IF($B43="","",INDEX(Takip!$A:$A,$B43)) -> S10078 | G43: =IF($B43="","",INDEX(Takip!$B:$B,$B43)) -> Emre Koç | H43: =IF($B43="","",INDEX(Takip!$Q:$Q,$B43)) -> Planla | I43: =IF($B43="","",INDEX(Takip!$K:$K,$B43)) -> 46495 | J43: =IF($B43="","",INDEX(Takip!$R:$R,$B43))
...

Sheet Takip
A1: Sicil No | B1: Ad Soyad | C1: Bölge | D1: Mağaza | E1: İşe Giriş | F1: Doğum Tarihi | G1: Kapsamda (1/0) | H1: Kıdem (yıl) | I1: Yaş | J1: Yıllık Hak (gün) | K1: Sonraki Hak Ediş | L1: Hak Edişe Kalan Gün | M1: Güncel Bakiye | N1: Önceki Bakiye | O1: Dönemde Kazanılan | P1: Dönemde Kullanılan | Q1: Bakiye Durumu | R1: Hak Ediş Yaklaşıyor | S1: Veri Notu | T1: Liste Anahtarı
A2: =IF(Veri_Guncel!A2="","",Veri_Guncel!A2) -> S10001 | B2: =IF($A2="","",Veri_Guncel!B2) -> Buse Yıldız | C2: =IF($A2="","",Veri_Guncel!C2) -> Bölge 1 | D2: =IF($A2="","",Veri_Guncel!D2) -> Mağaza 1A | E2: =IF($A2="","",Veri_Guncel!E2) -> 45606 | F2: =IF($A2="","",Veri_Guncel!F2) -> 37372 | G2: =IF(A2="","",IF(COUNTIF(Ayarlar!$A$15:$A$20,C2)>0,1,0)) -> 1 | H2: =IF(A2="","",DATEDIF(E2,Ayarlar!$B$3,"y")) -> 1 | I2: =IF(OR(A2="",F2=""),"",DATEDIF(F2,Ayarlar!$B$3,"y")) -> 24 | J2: =IF(A2="","",IF(H2<1,0,MAX(IF(H2<5,14,IF(H2<15,20,26)),IF(AND(I2<>"",OR(I2<=18,I2>=50)),20,0)))) -> 14 | K2: =IF(A2="","",EDATE(E2,12*(H2+1))) -> 46336 | L2: =IF(A2="","",K2-Ayarlar!$B$3) -> 57 | M2: =IF(A2="","",Veri_Guncel!H2) -> 14 | N2: =IF(A2="","",IFERROR(INDEX(Veri_Onceki!$H:$H,MATCH(A2,Veri_Onceki!$A:$A,0)),"")) -> 17 | O2: =IF(A2="","",IF(AND(H2>=1,EDATE(E2,12*H2)>Ayarlar!$B$4,EDATE(E2,12*H2)<=Ayarlar!$B$3),J2,0)) -> 0 | P2: =IF(OR(A2="",N2=""),"",N2+O2-M2) -> 3 | Q2: =IF(A2="","",IF(M2>=Ayarlar!$B$7,"ALARM",IF(M2>=Ayarlar!$B$6,"Planla",""))) -> Planla | R2: =IF(A2="","",IF(AND(L2>=0,L2<=Ayarlar!$B$9),"Evet","")) -> Evet | S2: =IF(A2="","",IF(N2="","Yeni personel",IF(P2<0,"Kontrol et",""))) | T2: =IF(A2="","",IF(AND(G2=1,M2>=Ayarlar!$B$6,OR(Ayarlar!$B$11="Tümü",C2=Ayarlar!$B$11)),M2+ROW()/100000,"")) -> 14.00002
A3: =IF(Veri_Guncel!A3="","",Veri_Guncel!A3) -> S10002 | B3: =IF($A3="","",Veri_Guncel!B3) -> Elif Öztürk | C3: =IF($A3="","",Veri_Guncel!C3) -> Bölge 1 | D3: =IF($A3="","",Veri_Guncel!D3) -> Mağaza 1A | E3: =IF($A3="","",Veri_Guncel!E3) -> 43101 | F3: =IF($A3="","",Veri_Guncel!F3) -> 34986 | G3: =IF(A3="","",IF(COUNTIF(Ayarlar!$A$15:$A$20,C3)>0,1,0)) -> 1 | H3: =IF(A3="","",DATEDIF(E3,Ayarlar!$B$3,"y")) -> 8 | I3: =IF(OR(A3="",F3=""),"",DATEDIF(F3,Ayarlar!$B$3,"y")) -> 30 | J3: =IF(A3="","",IF(H3<1,0,MAX(IF(H3<5,14,IF(H3<15,20,26)),IF(AND(I3<>"",OR(I3<=18,I3>=50)),20,0)))) -> 20 | K3: =IF(A3="","",EDATE(E3,12*(H3+1))) -> 46388 | L3: =IF(A3="","",K3-Ayarlar!$B$3) -> 109 | M3: =IF(A3="","",Veri_Guncel!H3) -> 2 | N3: =IF(A3="","",IFERROR(INDEX(Veri_Onceki!$H:$H,MATCH(A3,Veri_Onceki!$A:$A,0)),"")) -> 5 | O3: =IF(A3="","",IF(AND(H3>=1,EDATE(E3,12*H3)>Ayarlar!$B$4,EDATE(E3,12*H3)<=Ayarlar!$B$3),J3,0)) -> 0 | P3: =IF(OR(A3="",N3=""),"",N3+O3-M3) -> 3 | Q3: =IF(A3="","",IF(M3>=Ayarlar!$B$7,"ALARM",IF(M3>=Ayarlar!$B$6,"Planla",""))) | R3: =IF(A3="","",IF(AND(L3>=0,L3<=Ayarlar!$B$9),"Evet","")) | S3: =IF(A3="","",IF(N3="","Yeni personel",IF(P3<0,"Kontrol et",""))) | T3: =IF(A3="","",IF(AND(G3=1,M3>=Ayarlar!$B$6,OR(Ayarlar!$B$11="Tümü",C3=Ayarlar!$B$11)),M3+ROW()/100000,""))
A4: =IF(Veri_Guncel!A4="","",Veri_Guncel!A4) -> S10003 | B4: =IF($A4="","",Veri_Guncel!B4) -> Serkan Özdemir | C4: =IF($A4="","",Veri_Guncel!C4) -> Bölge 1 | D4: =IF($A4="","",Veri_Guncel!D4) -> Mağaza 1A | E4: =IF($A4="","",Veri_Guncel!E4) -> 43436 | F4: =IF($A4="","",Veri_Guncel!F4) -> 36519 | G4: =IF(A4="","",IF(COUNTIF(Ayarlar!$A$15:$A$20,C4)>0,1,0)) -> 1 | H4: =IF(A4="","",DATEDIF(E4,Ayarlar!$B$3,"y")) -> 7 | I4: =IF(OR(A4="",F4=""),"",DATEDIF(F4,Ayarlar!$B$3,"y")) -> 26 | J4: =IF(A4="","",IF(H4<1,0,MAX(IF(H4<5,14,IF(H4<15,20,26)),IF(AND(I4<>"",OR(I4<=18,I4>=50)),20,0)))) -> 20 | K4: =IF(A4="","",EDATE(E4,12*(H4+1))) -> 46358 | L4: =IF(A4="","",K4-Ayarlar!$B$3) -> 79 | M4: =IF(A4="","",Veri_Guncel!H4) -> 12 | N4: =IF(A4="","",IFERROR(INDEX(Veri_Onceki!$H:$H,MATCH(A4,Veri_Onceki!$A:$A,0)),"")) -> 19 | O4: =IF(A4="","",IF(AND(H4>=1,EDATE(E4,12*H4)>Ayarlar!$B$4,EDATE(E4,12*H4)<=Ayarlar!$B$3),J4,0)) -> 0 | P4: =IF(OR(A4="",N4=""),"",N4+O4-M4) -> 7 | Q4: =IF(A4="","",IF(M4>=Ayarlar!$B$7,"ALARM",IF(M4>=Ayarlar!$B$6,"Planla",""))) | R4: =IF(A4="","",IF(AND(L4>=0,L4<=Ayarlar!$B$9),"Evet","")) | S4: =IF(A4="","",IF(N4="","Yeni personel",IF(P4<0,"Kontrol et",""))) | T4: =IF(A4="","",IF(AND(G4=1,M4>=Ayarlar!$B$6,OR(Ayarlar!$B$11="Tümü",C4=Ayarlar!$B$11)),M4+ROW()/100000,""))
A5: =IF(Veri_Guncel!A5="","",Veri_Guncel!A5) -> S10004 | B5: =IF($A5="","",Veri_Guncel!B5) -> Onur Yılmaz | C5: =IF($A5="","",Veri_Guncel!C5) -> Bölge 1 | D5: =IF($A5="","",Veri_Guncel!D5) -> Mağaza 1A | E5: =IF($A5="","",Veri_Guncel!E5) -> 41078 | F5: =IF($A5="","",Veri_Guncel!F5) -> 37959 | G5: =IF(A5="","",IF(COUNTIF(Ayarlar!$A$15:$A$20,C5)>0,1,0)) -> 1 | H5: =IF(A5="","",DATEDIF(E5,Ayarlar!$B$3,"y")) -> 14 | I5: =IF(OR(A5="",F5=""),"",DATEDIF(F5,Ayarlar!$B$3,"y")) -> 22 | J5: =IF(A5="","",IF(H5<1,0,MAX(IF(H5<5,14,IF(H5<15,20,26)),IF(AND(I5<>"",OR(I5<=18,I5>=50)),20,0)))) -> 20 | K5: =IF(A5="","",EDATE(E5,12*(H5+1))) -> 46556 | L5: =IF(A5="","",K5-Ayarlar!$B$3) -> 277 | M5: =IF(A5="","",Veri_Guncel!H5) -> 19 | N5: =IF(A5="","",IFERROR(INDEX(Veri_Onceki!$H:$H,MATCH(A5,Veri_Onceki!$A:$A,0)),"")) -> 21 | O5: =IF(A5="","",IF(AND(H5>=1,EDATE(E5,12*H5)>Ayarlar!$B$4,EDATE(E5,12*H5)<=Ayarlar!$B$3),J5,0)) -> 0 | P5: =IF(OR(A5="",N5=""),"",N5+O5-M5) -> 2 | Q5: =IF(A5="","",IF(M5>=Ayarlar!$B$7,"ALARM",IF(M5>=Ayarlar!$B$6,"Planla",""))) -> Planla | R5: =IF(A5="","",IF(AND(L5>=0,L5<=Ayarlar!$B$9),"Evet","")) | S5: =IF(A5="","",IF(N5="","Yeni personel",IF(P5<0,"Kontrol et",""))) | T5: =IF(A5="","",IF(AND(G5=1,M5>=Ayarlar!$B$6,OR(Ayarlar!$B$11="Tümü",C5=Ayarlar!$B$11)),M5+ROW()/100000,"")) -> 19.00005
A6: =IF(Veri_Guncel!A6="","",Veri_Guncel!A6) -> S10005 | B6: =IF($A6="","",Veri_Guncel!B6) -> İrem Yıldız | C6: =IF($A6="","",Veri_Guncel!C6) -> Bölge 1 | D6: =IF($A6="","",Veri_Guncel!D6) -> Mağaza 1A | E6: =IF($A6="","",Veri_Guncel!E6) -> 42365 | F6: =IF($A6="","",Veri_Guncel!F6) -> 28182 | G6: =IF(A6="","",IF(COUNTIF(Ayarlar!$A$15:$A$20,C6)>0,1,0)) -> 1 | H6: =IF(A6="","",DATEDIF(E6,Ayarlar!$B$3,"y")) -> 10 | I6: =IF(OR(A6="",F6=""),"",DATEDIF(F6,Ayarlar!$B$3,"y")) -> 49 | J6: =IF(A6="","",IF(H6<1,0,MAX(IF(H6<5,14,IF(H6<15,20,26)),IF(AND(I6<>"",OR(I6<=18,I6>=50)),20,0)))) -> 20 | K6: =IF(A6="","",EDATE(E6,12*(H6+1))) -> 46383 | L6: =IF(A6="","",K6-Ayarlar!$B$3) -> 104 | M6: =IF(A6="","",Veri_Guncel!H6) -> 0 | N6: =IF(A6="","",IFERROR(INDEX(Veri_Onceki!$H:$H,MATCH(A6,Veri_Onceki!$A:$A,0)),"")) -> 7 | O6: =IF(A6="","",IF(AND(H6>=1,EDATE(E6,12*H6)>Ayarlar!$B$4,EDATE(E6,12*H6)<=Ayarlar!$B$3),J6,0)) -> 0 | P6: =IF(OR(A6="",N6=""),"",N6+O6-M6) -> 7 | Q6: =IF(A6="","",IF(M6>=Ayarlar!$B$7,"ALARM",IF(M6>=Ayarlar!$B$6,"Planla",""))) | R6: =IF(A6="","",IF(AND(L6>=0,L6<=Ayarlar!$B$9),"Evet","")) | S6: =IF(A6="","",IF(N6="","Yeni personel",IF(P6<0,"Kontrol et",""))) | T6: =IF(A6="","",IF(AND(G6=1,M6>=Ayarlar!$B$6,OR(Ayarlar!$B$11="Tümü",C6=Ayarlar!$B$11)),M6+ROW()/100000,""))
A7: =IF(Veri_Guncel!A7="","",Veri_Guncel!A7) -> S10006 | B7: =IF($A7="","",Veri_Guncel!B7) -> Cem Öztürk | C7: =IF($A7="","",Veri_Guncel!C7) -> Bölge 1 | D7: =IF($A7="","",Veri_Guncel!D7) -> Mağaza 1A | E7: =IF($A7="","",Veri_Guncel!E7) -> 44393 | F7: =IF($A7="","",Veri_Guncel!F7) -> 29667 | G7: =IF(A7="","",IF(COUNTIF(Ayarlar!$A$15:$A$20,C7)>0,1,0)) -> 1 | H7: =IF(A7="","",DATEDIF(E7,Ayarlar!$B$3,"y")) -> 5 | I7: =IF(OR(A7="",F7=""),"",DATEDIF(F7,Ayarlar!$B$3,"y")) -> 45 | J7: =IF(A7="","",IF(H7<1,0,MAX(IF(H7<5,14,IF(H7<15,20,26)),IF(AND(I7<>"",OR(I7<=18,I7>=50)),20,0)))) -> 20 | K7: =IF(A7="","",EDATE(E7,12*(H7+1))) -> 46584 | L7: =IF(A7="","",K7-Ayarlar!$B$3) -> 305 | M7: =IF(A7="","",Veri_Guncel!H7) -> 0 | N7: =IF(A7="","",IFERROR(INDEX(Veri_Onceki!$H:$H,MATCH(A7,Veri_Onceki!$A:$A,0)),"")) -> 0 | O7: =IF(A7="","",IF(AND(H7>=1,EDATE(E7,12*H7)>Ayarlar!$B$4,EDATE(E7,12*H7)<=Ayarlar!$B$3),J7,0)) -> 0 | P7: =IF(OR(A7="",N7=""),"",N7+O7-M7) -> 0 | Q7: =IF(A7="","",IF(M7>=Ayarlar!$B$7,"ALARM",IF(M7>=Ayarlar!$B$6,"Planla",""))) | R7: =IF(A7="","",IF(AND(L7>=0,L7<=Ayarlar!$B$9),"Evet","")) | S7: =IF(A7="","",IF(N7="","Yeni personel",IF(P7<0,"Kontrol et",""))) | T7: =IF(A7="","",IF(AND(G7=1,M7>=Ayarlar!$B$6,OR(Ayarlar!$B$11="Tümü",C7=Ayarlar!$B$11)),M7+ROW()/100000,""))
A8: =IF(Veri_Guncel!A8="","",Veri_Guncel!A8) -> S10007 | B8: =IF($A8="","",Veri_Guncel!B8) -> Tolga Koç | C8: =IF($A8="","",Veri_Guncel!C8) -> Bölge 1 | D8: =IF($A8="","",Veri_Guncel!D8) -> Mağaza 1A | E8: =IF($A8="","",Veri_Guncel!E8) -> 41371 | F8: =IF($A8="","",Veri_Guncel!F8) -> 27808 | G8: =IF(A8="","",IF(COUNTIF(Ayarlar!$A$15:$A$20,C8)>0,1,0)) -> 1 | H8: =IF(A8="","",DATEDIF(E8,Ayarlar!$B$3,"y")) -> 13 | I8: =IF(OR(A8="",F8=""),"",DATEDIF(F8,Ayarlar!$B$3,"y")) -> 50 | J8: =IF(A8="","",IF(H8<1,0,MAX(IF(H8<5,14,IF(H8<15,20,26)),IF(AND(I8<>"",OR(I8<=18,I8>=50)),20,0)))) -> 20 | K8: =IF(A8="","",EDATE(E8,12*(H8+1))) -> 46484 | L8: =IF(A8="","",K8-Ayarlar!$B$3) -> 205 | M8: =IF(A8="","",Veri_Guncel!H8) -> 14 | N8: =IF(A8="","",IFERROR(INDEX(Veri_Onceki!$H:$H,MATCH(A8,Veri_Onceki!$A:$A,0)),"")) -> 16 | O8: =IF(A8="","",IF(AND(H8>=1,EDATE(E8,12*H8)>Ayarlar!$B$4,EDATE(E8,12*H8)<=Ayarlar!$B$3),J8,0)) -> 0 | P8: =IF(OR(A8="",N8=""),"",N8+O8-M8) -> 2 | Q8: =IF(A8="","",IF(M8>=Ayarlar!$B$7,"ALARM",IF(M8>=Ayarlar!$B$6,"Planla",""))) -> Planla | R8: =IF(A8="","",IF(AND(L8>=0,L8<=Ayarlar!$B$9),"Evet","")) | S8: =IF(A8="","",IF(N8="","Yeni personel",IF(P8<0,"Kontrol et",""))) | T8: =IF(A8="","",IF(AND(G8=1,M8>=Ayarlar!$B$6,OR(Ayarlar!$B$11="Tümü",C8=Ayarlar!$B$11)),M8+ROW()/100000,"")) -> 14.00008
A9: =IF(Veri_Guncel!A9="","",Veri_Guncel!A9) -> S10008 | B9: =IF($A9="","",Veri_Guncel!B9) -> İrem Koç | C9: =IF($A9="","",Veri_Guncel!C9) -> Bölge 1 | D9: =IF($A9="","",Veri_Guncel!D9) -> Mağaza 1A | E9: =IF($A9="","",Veri_Guncel!E9) -> 42891 | F9: =IF($A9="","",Veri_Guncel!F9) -> 38908 | G9: =IF(A9="","",IF(COUNTIF(Ayarlar!$A$15:$A$20,C9)>0,1,0)) -> 1 | H9: =IF(A9="","",DATEDIF(E9,Ayarlar!$B$3,"y")) -> 9 | I9: =IF(OR(A9="",F9=""),"",DATEDIF(F9,Ayarlar!$B$3,"y")) -> 20 | J9: =IF(A9="","",IF(H9<1,0,MAX(IF(H9<5,14,IF(H9<15,20,26)),IF(AND(I9<>"",OR(I9<=18,I9>=50)),20,0)))) -> 20 | K9: =IF(A9="","",EDATE(E9,12*(H9+1))) -> 46543 | L9: =IF(A9="","",K9-Ayarlar!$B$3) -> 264 | M9: =IF(A9="","",Veri_Guncel!H9) -> 10 | N9: =IF(A9="","",IFERROR(INDEX(Veri_Onceki!$H:$H,MATCH(A9,Veri_Onceki!$A:$A,0)),"")) -> 17 | O9: =IF(A9="","",IF(AND(H9>=1,EDATE(E9,12*H9)>Ayarlar!$B$4,EDATE(E9,12*H9)<=Ayarlar!$B$3),J9,0)) -> 0 | P9: =IF(OR(A9="",N9=""),"",N9+O9-M9) -> 7 | Q9: =IF(A9="","",IF(M9>=Ayarlar!$B$7,"ALARM",IF(M9>=Ayarlar!$B$6,"Planla",""))) | R9: =IF(A9="","",IF(AND(L9>=0,L9<=Ayarlar!$B$9),"Evet","")) | S9: =IF(A9="","",IF(N9="","Yeni personel",IF(P9<0,"Kontrol et",""))) | T9: =IF(A9="","",IF(AND(G9=1,M9>=Ayarlar!$B$6,OR(Ayarlar!$B$11="Tümü",C9=Ayarlar!$B$11)),M9+ROW()/100000,""))
A10: =IF(Veri_Guncel!A10="","",Veri_Guncel!A10) -> S10009 | B10: =IF($A10="","",Veri_Guncel!B10) -> Pınar Polat | C10: =IF($A10="","",Veri_Guncel!C10) -> Bölge 1 | D10: =IF($A10="","",Veri_Guncel!D10) -> Mağaza 1B | E10: =IF($A10="","",Veri_Guncel!E10) -> 46212 | F10: =IF($A10="","",Veri_Guncel!F10) -> 26701 | G10: =IF(A10="","",IF(COUNTIF(Ayarlar!$A$15:$A$20,C10)>0,1,0)) -> 1 | H10: =IF(A10="","",DATEDIF(E10,Ayarlar!$B$3,"y")) -> 0 | I10: =IF(OR(A10="",F10=""),"",DATEDIF(F10,Ayarlar!$B$3,"y")) -> 53 | J10: =IF(A10="","",IF(H10<1,0,MAX(IF(H10<5,14,IF(H10<15,20,26)),IF(AND(I10<>"",OR(I10<=18,I10>=50)),20,0)))) -> 0 | K10: =IF(A10="","",EDATE(E10,12*(H10+1))) -> 46577 | L10: =IF(A10="","",K10-Ayarlar!$B$3) -> 298 | M10: =IF(A10="","",Veri_Guncel!H10) -> 0 | N10: =IF(A10="","",IFERROR(INDEX(Veri_Onceki!$H:$H,MATCH(A10,Veri_Onceki!$A:$A,0)),"")) -> 0 | O10: =IF(A10="","",IF(AND(H10>=1,EDATE(E10,12*H10)>Ayarlar!$B$4,EDATE(E10,12*H10)<=Ayarlar!$B$3),J10,0)) -> 0 | P10: =IF(OR(A10="",N10=""),"",N10+O10-M10) -> 0 | Q10: =IF(A10="","",IF(M10>=Ayarlar!$B$7,"ALARM",IF(M10>=Ayarlar!$B$6,"Planla",""))) | R10: =IF(A10="","",IF(AND(L10>=0,L10<=Ayarlar!$B$9),"Evet","")) | S10: =IF(A10="","",IF(N10="","Yeni personel",IF(P10<0,"Kontrol et",""))) | T10: =IF(A10="","",IF(AND(G10=1,M10>=Ayarlar!$B$6,OR(Ayarlar!$B$11="Tümü",C10=Ayarlar!$B$11)),M10+ROW()/100000,""))
A11: =IF(Veri_Guncel!A11="","",Veri_Guncel!A11) -> S10010 | B11: =IF($A11="","",Veri_Guncel!B11) -> Burak Kılıç | C11: =IF($A11="","",Veri_Guncel!C11) -> Bölge 1 | D11: =IF($A11="","",Veri_Guncel!D11) -> Mağaza 1B | E11: =IF($A11="","",Veri_Guncel!E11) -> 40758 | F11: =IF($A11="","",Veri_Guncel!F11) -> 39379 | G11: =IF(A11="","",IF(COUNTIF(Ayarlar!$A$15:$A$20,C11)>0,1,0)) -> 1 | H11: =IF(A11="","",DATEDIF(E11,Ayarlar!$B$3,"y")) -> 15 | I11: =IF(OR(A11="",F11=""),"",DATEDIF(F11,Ayarlar!$B$3,"y")) -> 18 | J11: =IF(A11="","",IF(H11<1,0,MAX(IF(H11<5,14,IF(H11<15,20,26)),IF(AND(I11<>"",OR(I11<=18,I11>=50)),20,0)))) -> 26 | K11: =IF(A11="","",EDATE(E11,12*(H11+1))) -> 46602 | L11: =IF(A11="","",K11-Ayarlar!$B$3) -> 323 | M11: =IF(A11="","",Veri_Guncel!H11) -> 15 | N11: =IF(A11="","",IFERROR(INDEX(Veri_Onceki!$H:$H,MATCH(A11,Veri_Onceki!$A:$A,0)),"")) -> 0 | O11: =IF(A11="","",IF(AND(H11>=1,EDATE(E11,12*H11)>Ayarlar!$B$4,EDATE(E11,12*H11)<=Ayarlar!$B$3),J11,0)) -> 26 | P11: =IF(OR(A11="",N11=""),"",N11+O11-M11) -> 11 | Q11: =IF(A11="","",IF(M11>=Ayarlar!$B$7,"ALARM",IF(M11>=Ayarlar!$B$6,"Planla",""))) -> Planla | R11: =IF(A11="","",IF(AND(L11>=0,L11<=Ayarlar!$B$9),"Evet","")) | S11: =IF(A11="","",IF(N11="","Yeni personel",IF(P11<0,"Kontrol et",""))) | T11: =IF(A11="","",IF(AND(G11=1,M11>=Ayarlar!$B$6,OR(Ayarlar!$B$11="Tümü",C11=Ayarlar!$B$11)),M11+ROW()/100000,"")) -> 15.00011
A12: =IF(Veri_Guncel!A12="","",Veri_Guncel!A12) -> S10011 | B12: =IF($A12="","",Veri_Guncel!B12) -> Ece Aslan | C12: =IF($A12="","",Veri_Guncel!C12) -> Bölge 1 | D12: =IF($A12="","",Veri_Guncel!D12) -> Mağaza 1B | E12: =IF($A12="","",Veri_Guncel!E12) -> 41720 | F12: =IF($A12="","",Veri_Guncel!F12) -> 30267 | G12: =IF(A12="","",IF(COUNTIF(Ayarlar!$A$15:$A$20,C12)>0,1,0)) -> 1 | H12: =IF(A12="","",DATEDIF(E12,Ayarlar!$B$3,"y")) -> 12 | I12: =IF(OR(A12="",F12=""),"",DATEDIF(F12,Ayarlar!$B$3,"y")) -> 43 | J12: =IF(A12="","",IF(H12<1,0,MAX(IF(H12<5,14,IF(H12<15,20,26)),IF(AND(I12<>"",OR(I12<=18,I12>=50)),20,0)))) -> 20 | K12: =IF(A12="","",EDATE(E12,12*(H12+1))) -> 46468 | L12: =IF(A12="","",K12-Ayarlar!$B$3) -> 189 | M12: =IF(A12="","",Veri_Guncel!H12) -> 28 | N12: =IF(A12="","",IFERROR(INDEX(Veri_Onceki!$H:$H,MATCH(A12,Veri_Onceki!$A:$A,0)),"")) -> 28 | O12: =IF(A12="","",IF(AND(H12>=1,EDATE(E12,12*H12)>Ayarlar!$B$4,EDATE(E12,12*H12)<=Ayarlar!$B$3),J12,0)) -> 0 | P12: =IF(OR(A12="",N12=""),"",N12+O12-M12) -> 0 | Q12: =IF(A12="","",IF(M12>=Ayarlar!$B$7,"ALARM",IF(M12>=Ayarlar!$B$6,"Planla",""))) -> ALARM | R12: =IF(A12="","",IF(AND(L12>=0,L12<=Ayarlar!$B$9),"Evet","")) | S12: =IF(A12="","",IF(N12="","Yeni personel",IF(P12<0,"Kontrol et",""))) | T12: =IF(A12="","",IF(AND(G12=1,M12>=Ayarlar!$B$6,OR(Ayarlar!$B$11="Tümü",C12=Ayarlar!$B$11)),M12+ROW()/100000,"")) -> 28.00012
A13: =IF(Veri_Guncel!A13="","",Veri_Guncel!A13) -> S10012 | B13: =IF($A13="","",Veri_Guncel!B13) -> Kaan Aslan | C13: =IF($A13="","",Veri_Guncel!C13) -> Bölge 1 | D13: =IF($A13="","",Veri_Guncel!D13) -> Mağaza 1B | E13: =IF($A13="","",Veri_Guncel!E13) -> 43925 | F13: =IF($A13="","",Veri_Guncel!F13) -> 30009 | G13: =IF(A13="","",IF(COUNTIF(Ayarlar!$A$15:$A$20,C13)>0,1,0)) -> 1 | H13: =IF(A13="","",DATEDIF(E13,Ayarlar!$B$3,"y")) -> 6 | I13: =IF(OR(A13="",F13=""),"",DATEDIF(F13,Ayarlar!$B$3,"y")) -> 44 | J13: =IF(A13="","",IF(H13<1,0,MAX(IF(H13<5,14,IF(H13<15,20,26)),IF(AND(I13<>"",OR(I13<=18,I13>=50)),20,0)))) -> 20 | K13: =IF(A13="","",EDATE(E13,12*(H13+1))) -> 46481 | L13: =IF(A13="","",K13-Ayarlar!$B$3) -> 202 | M13: =IF(A13="","",Veri_Guncel!H13) -> 4 | N13: =IF(A13="","",IFERROR(INDEX(Veri_Onceki!$H:$H,MATCH(A13,Veri_Onceki!$A:$A,0)),"")) -> 4 | O13: =IF(A13="","",IF(AND(H13>=1,EDATE(E13,12*H13)>Ayarlar!$B$4,EDATE(E13,12*H13)<=Ayarlar!$B$3),J13,0)) -> 0 | P13: =IF(OR(A13="",N13=""),"",N13+O13-M13) -> 0 | Q13: =IF(A13="","",IF(M13>=Ayarlar!$B$7,"ALARM",IF(M13>=Ayarlar!$B$6,"Planla",""))) | R13: =IF(A13="","",IF(AND(L13>=0,L13<=Ayarlar!$B$9),"Evet","")) | S13: =IF(A13="","",IF(N13="","Yeni personel",IF(P13<0,"Kontrol et",""))) | T13: =IF(A13="","",IF(AND(G13=1,M13>=Ayarlar!$B$6,OR(Ayarlar!$B$11="Tümü",C13=Ayarlar!$B$11)),M13+ROW()/100000,""))
... A501: =IF(Veri_Guncel!A501="","",Veri_Guncel!A501) | B501: =IF($A501="","",Veri_Guncel!B501) | C501: =IF($A501="","",Veri_Guncel!C501) | D501: =IF($A501="","",Veri_Guncel!D501) | E501: =IF($A501="","",Veri_Guncel!E501) | F501: =IF($A501="","",Veri_Guncel!F501) | G501: =IF(A501="","",IF(COUNTIF(Ayarlar!$A$15:$A$20,C501)>0,1,0)) | H501: =IF(A501="","",DATEDIF(E501,Ayarlar!$B$3,"y")) | I501: =IF(OR(A501="",F501=""),"",DATEDIF(F501,Ayarlar!$B$3,"y")) | J501: =IF(A501="","",IF(H501<1,0,MAX(IF(H501<5,14,IF(H501<15,20,26)),IF(AND(I501<>"",OR(I501<=18,I501>=50)),20,0)))) | K501: =IF(A501="","",EDATE(E501,12*(H501+1))) | L501: =IF(A501="","",K501-Ayarlar!$B$3) | M501: =IF(A501="","",Veri_Guncel!H501) | N501: =IF(A501="","",IFERROR(INDEX(Veri_Onceki!$H:$H,MATCH(A501,Veri_Onceki!$A:$A,0)),"")) | O501: =IF(A501="","",IF(AND(H501>=1,EDATE(E501,12*H501)>Ayarlar!$B$4,EDATE(E501,12*H501)<=Ayarlar!$B$3),J501,0)) | P501: =IF(OR(A501="",N501=""),"",N501+O501-M501) | Q501: =IF(A501="","",IF(M501>=Ayarlar!$B$7,"ALARM",IF(M501>=Ayarlar!$B$6,"Planla",""))) | R501: =IF(A501="","",IF(AND(L501>=0,L501<=Ayarlar!$B$9),"Evet","")) | S501: =IF(A501="","",IF(N501="","Yeni personel",IF(P501<0,"Kontrol et",""))) | T501: =IF(A501="","",IF(AND(G501=1,M501>=Ayarlar!$B$6,OR(Ayarlar!$B$11="Tümü",C501=Ayarlar!$B$11)),M501+ROW()/100000,""))

Sheet Ayarlar
A1: Ayarlar
A3: Güncel data tarihi | B3: 46279
A4: Önceki data tarihi | B4: 46234
A6: Planlama eşiği (gün) | B6: 14 | C6: Bu bakiyenin üstü izin planlamasına alınır
A7: Alarm eşiği (gün) | B7: 20
A8: Bölge alarmı: alarm eşiğini aşan kişi sayısı | B8: 5 | C8: Bu sayıya ulaşan bölgede Ozet'te ALARM çıkar
A9: Yaklaşan hak ediş penceresi (gün) | B9: 60
A11: Liste bölgesi | B11: Tümü | C11: Tümü veya tek bölge — Liste_14_Gun sayfasını filtreler
A14: Takip edilen bölgeler | E14: Liste seçenekleri
A15: Bölge 1 | B15: Listede olmayan bölgeler (ör. tüm Türkiye datası) hesaplara girmez. | E15: Tümü
A16: Bölge 2 | E16: =A15 -> Bölge 1
A17: Bölge 3 | E17: =A16 -> Bölge 2
A18: Bölge 4 | E18: =A17 -> Bölge 3
A19: Bölge 5 | E19: =A18 -> Bölge 4
A20: Bölge 6 | E20: =A19 -> Bölge 5
E21: =A20 -> Bölge 6

Sheet Veri_Guncel
A1: Sicil No | B1: Ad Soyad | C1: Bölge | D1: Mağaza | E1: İşe Giriş Tarihi | F1: Doğum Tarihi | G1: Görev | H1: Kalan İzin (gün)
A2: S10001 | B2: Buse Yıldız | C2: Bölge 1 | D2: Mağaza 1A | E2: 45606 | F2: 37372 | G2: Vardiya Sorumlusu | H2: 14
A3: S10002 | B3: Elif Öztürk | C3: Bölge 1 | D3: Mağaza 1A | E3: 43101 | F3: 34986 | G3: Müdür Yardımcısı | H3: 2
A4: S10003 | B4: Serkan Özdemir | C4: Bölge 1 | D4: Mağaza 1A | E4: 43436 | F4: 36519 | G4: Barista | H4: 12
A5: S10004 | B5: Onur Yılmaz | C5: Bölge 1 | D5: Mağaza 1A | E5: 41078 | F5: 37959 | G5: Barista | H5: 19
A6: S10005 | B6: İrem Yıldız | C6: Bölge 1 | D6: Mağaza 1A | E6: 42365 | F6: 28182 | G6: Barista | H6: 0
A7: S10006 | B7: Cem Öztürk | C7: Bölge 1 | D7: Mağaza 1A | E7: 44393 | F7: 29667 | G7: Barista | H7: 0
A8: S10007 | B8: Tolga Koç | C8: Bölge 1 | D8: Mağaza 1A | E8: 41371 | F8: 27808 | G8: Müdür Yardımcısı | H8: 14
A9: S10008 | B9: İrem Koç | C9: Bölge 1 | D9: Mağaza 1A | E9: 42891 | F9: 38908 | G9: Vardiya Sorumlusu | H9: 10
A10: S10009 | B10: Pınar Polat | C10: Bölge 1 | D10: Mağaza 1B | E10: 46212 | F10: 26701 | G10: Müdür Yardımcısı | H10: 0
A11: S10010 | B11: Burak Kılıç | C11: Bölge 1 | D11: Mağaza 1B | E11: 40758 | F11: 39379 | G11: Müdür Yardımcısı | H11: 15
A12: S10011 | B12: Ece Aslan | C12: Bölge 1 | D12: Mağaza 1B | E12: 41720 | F12: 30267 | G12: Müdür Yardımcısı | H12: 28
A13: S10012 | B13: Kaan Aslan | C13: Bölge 1 | D13: Mağaza 1B | E13: 43925 | F13: 30009 | G13: Barista | H13: 4
... A190: S10189 | B190: Kaan Yılmaz | C190: Bölge 4 | D190: Mağaza 4A | E190: 46244 | F190: 38119 | G190: Müdür Yardımcısı | H190: 0

Sheet Veri_Onceki
A1: Sicil No | B1: Ad Soyad | C1: Bölge | D1: Mağaza | E1: İşe Giriş Tarihi | F1: Doğum Tarihi | G1: Görev | H1: Kalan İzin (gün) | I1: Ayrıldı mı? (yardımcı)
A2: S10001 | B2: Buse Yıldız | C2: Bölge 1 | D2: Mağaza 1A | E2: 45606 | F2: 37372 | G2: Müdür Yardımcısı | H2: 17 | I2: =IF(A2="","",IF(COUNTIF(Veri_Guncel!$A:$A,A2)=0,1,0)) -> 0
A3: S10002 | B3: Elif Öztürk | C3: Bölge 1 | D3: Mağaza 1A | E3: 43101 | F3: 34986 | G3: Müdür Yardımcısı | H3: 5 | I3: =IF(A3="","",IF(COUNTIF(Veri_Guncel!$A:$A,A3)=0,1,0)) -> 0
A4: S10003 | B4: Serkan Özdemir | C4: Bölge 1 | D4: Mağaza 1A | E4: 43436 | F4: 36519 | G4: Vardiya Sorumlusu | H4: 19 | I4: =IF(A4="","",IF(COUNTIF(Veri_Guncel!$A:$A,A4)=0,1,0)) -> 0
A5: S10004 | B5: Onur Yılmaz | C5: Bölge 1 | D5: Mağaza 1A | E5: 41078 | F5: 37959 | G5: Barista | H5: 21 | I5: =IF(A5="","",IF(COUNTIF(Veri_Guncel!$A:$A,A5)=0,1,0)) -> 0
A6: S10005 | B6: İrem Yıldız | C6: Bölge 1 | D6: Mağaza 1A | E6: 42365 | F6: 28182 | G6: Barista | H6: 7 | I6: =IF(A6="","",IF(COUNTIF(Veri_Guncel!$A:$A,A6)=0,1,0)) -> 0
A7: S10006 | B7: Cem Öztürk | C7: Bölge 1 | D7: Mağaza 1A | E7: 44393 | F7: 29667 | G7: Barista | H7: 0 | I7: =IF(A7="","",IF(COUNTIF(Veri_Guncel!$A:$A,A7)=0,1,0)) -> 0
A8: S10007 | B8: Tolga Koç | C8: Bölge 1 | D8: Mağaza 1A | E8: 41371 | F8: 27808 | G8: Barista | H8: 16 | I8: =IF(A8="","",IF(COUNTIF(Veri_Guncel!$A:$A,A8)=0,1,0)) -> 0
A9: S10008 | B9: İrem Koç | C9: Bölge 1 | D9: Mağaza 1A | E9: 42891 | F9: 38908 | G9: Vardiya Sorumlusu | H9: 17 | I9: =IF(A9="","",IF(COUNTIF(Veri_Guncel!$A:$A,A9)=0,1,0)) -> 0
A10: S10009 | B10: Pınar Polat | C10: Bölge 1 | D10: Mağaza 1B | E10: 46212 | F10: 26701 | G10: Barista | H10: 0 | I10: =IF(A10="","",IF(COUNTIF(Veri_Guncel!$A:$A,A10)=0,1,0)) -> 0
A11: S10010 | B11: Burak Kılıç | C11: Bölge 1 | D11: Mağaza 1B | E11: 40758 | F11: 39379 | G11: Barista | H11: 0 | I11: =IF(A11="","",IF(COUNTIF(Veri_Guncel!$A:$A,A11)=0,1,0)) -> 0
A12: S10011 | B12: Ece Aslan | C12: Bölge 1 | D12: Mağaza 1B | E12: 41720 | F12: 30267 | G12: Müdür Yardımcısı | H12: 28 | I12: =IF(A12="","",IF(COUNTIF(Veri_Guncel!$A:$A,A12)=0,1,0)) -> 0
A13: S10012 | B13: Kaan Aslan | C13: Bölge 1 | D13: Mağaza 1B | E13: 43925 | F13: 30009 | G13: Müdür Yardımcısı | H13: 4 | I13: =IF(A13="","",IF(COUNTIF(Veri_Guncel!$A:$A,A13)=0,1,0)) -> 0
... A192: S10195 | B192: Oğuz Doğan | C192: Bölge 2 | D192: Mağaza 2A | E192: 43819 | F192: 33940 | G192: Müdür Yardımcısı | H192: 6 | I192: =IF(A192="","",IF(COUNTIF(Veri_Guncel!$A:$A,A192)=0,1,0)) -> 1
I193: =IF(A193="","",IF(COUNTIF(Veri_Guncel!$A:$A,A193)=0,1,0))
I194: =IF(A194="","",IF(COUNTIF(Veri_Guncel!$A:$A,A194)=0,1,0))
I195: =IF(A195="","",IF(COUNTIF(Veri_Guncel!$A:$A,A195)=0,1,0))
I196: =IF(A196="","",IF(COUNTIF(Veri_Guncel!$A:$A,A196)=0,1,0))
I197: =IF(A197="","",IF(COUNTIF(Veri_Guncel!$A:$A,A197)=0,1,0))
I198: =IF(A198="","",IF(COUNTIF(Veri_Guncel!$A:$A,A198)=0,1,0))
I199: =IF(A199="","",IF(COUNTIF(Veri_Guncel!$A:$A,A199)=0,1,0))
I200: =IF(A200="","",IF(COUNTIF(Veri_Guncel!$A:$A,A200)=0,1,0))
I201: =IF(A201="","",IF(COUNTIF(Veri_Guncel!$A:$A,A201)=0,1,0))
I202: =IF(A202="","",IF(COUNTIF(Veri_Guncel!$A:$A,A202)=0,1,0))
I203: =IF(A203="","",IF(COUNTIF(Veri_Guncel!$A:$A,A203)=0,1,0))
I204: =IF(A204="","",IF(COUNTIF(Veri_Guncel!$A:$A,A204)=0,1,0))
... I501: =IF(A501="","",IF(COUNTIF(Veri_Guncel!$A:$A,A501)=0,1,0))
